2023-06-10 11:18:38 [ERROR] /Users/sumith/Documents/Projects/vercel/phenv/lib/python3.9/site-packages/django/utils/log.py:241 Internal Server Error: /signup/
Traceback (most recent call last):
  File "/Users/sumith/Documents/Projects/vercel/phenv/lib/python3.9/site-packages/rest_framework/views.py", line 497, in dispatch
    self.initial(request, *args, **kwargs)
  File "/Users/sumith/Documents/Projects/vercel/phenv/lib/python3.9/site-packages/rest_framework/views.py", line 414, in initial
    self.perform_authentication(request)
  File "/Users/sumith/Documents/Projects/vercel/phenv/lib/python3.9/site-packages/rest_framework/views.py", line 324, in perform_authentication
    request.user
  File "/Users/sumith/Documents/Projects/vercel/phenv/lib/python3.9/site-packages/rest_framework/request.py", line 227, in user
    self._authenticate()
  File "/Users/sumith/Documents/Projects/vercel/phenv/lib/python3.9/site-packages/rest_framework/request.py", line 380, in _authenticate
    user_auth_tuple = authenticator.authenticate(self)
  File "/Users/sumith/Documents/Projects/vercel/phenv/lib/python3.9/site-packages/rest_framework/authentication.py", line 130, in authenticate
    self.enforce_csrf(request)
  File "/Users/sumith/Documents/Projects/vercel/phenv/lib/python3.9/site-packages/rest_framework/authentication.py", line 148, in enforce_csrf
    raise exceptions.PermissionDenied('CSRF Failed: %s' % reason)
rest_framework.exceptions.PermissionDenied: CSRF Failed: CSRF token missing.

During handling of the above exception, another exception occurred:

Traceback (most recent call last):
  File "/Users/sumith/Documents/Projects/vercel/phenv/lib/python3.9/site-packages/rest_framework/settings.py", line 177, in import_from_string
    return import_string(val)
  File "/Users/sumith/Documents/Projects/vercel/phenv/lib/python3.9/site-packages/django/utils/module_loading.py", line 30, in import_string
    return cached_import(module_path, class_name)
  File "/Users/sumith/Documents/Projects/vercel/phenv/lib/python3.9/site-packages/django/utils/module_loading.py", line 15, in cached_import
    module = import_module(module_path)
  File "/Users/sumith/opt/anaconda3/lib/python3.9/importlib/__init__.py", line 127, in import_module
    return _bootstrap._gcd_import(name[level:], package, level)
  File "<frozen importlib._bootstrap>", line 1030, in _gcd_import
  File "<frozen importlib._bootstrap>", line 1007, in _find_and_load
  File "<frozen importlib._bootstrap>", line 972, in _find_and_load_unlocked
  File "<frozen importlib._bootstrap>", line 228, in _call_with_frames_removed
  File "<frozen importlib._bootstrap>", line 1030, in _gcd_import
  File "<frozen importlib._bootstrap>", line 1007, in _find_and_load
  File "<frozen importlib._bootstrap>", line 972, in _find_and_load_unlocked
  File "<frozen importlib._bootstrap>", line 228, in _call_with_frames_removed
  File "<frozen importlib._bootstrap>", line 1030, in _gcd_import
  File "<frozen importlib._bootstrap>", line 1007, in _find_and_load
  File "<frozen importlib._bootstrap>", line 984, in _find_and_load_unlocked
ModuleNotFoundError: No module named 'your_project_name'

During handling of the above exception, another exception occurred:

Traceback (most recent call last):
  File "/Users/sumith/Documents/Projects/vercel/phenv/lib/python3.9/site-packages/django/core/handlers/exception.py", line 55, in inner
    response = get_response(request)
  File "/Users/sumith/Documents/Projects/vercel/phenv/lib/python3.9/site-packages/django/core/handlers/base.py", line 197, in _get_response
    response = wrapped_callback(request, *callback_args, **callback_kwargs)
  File "/Users/sumith/Documents/Projects/vercel/phenv/lib/python3.9/site-packages/django/views/decorators/csrf.py", line 56, in wrapper_view
    return view_func(*args, **kwargs)
  File "/Users/sumith/Documents/Projects/vercel/phenv/lib/python3.9/site-packages/django/views/generic/base.py", line 104, in view
    return self.dispatch(request, *args, **kwargs)
  File "/Users/sumith/Documents/Projects/vercel/phenv/lib/python3.9/site-packages/django/views/decorators/csrf.py", line 56, in wrapper_view
    return view_func(*args, **kwargs)
  File "/Users/sumith/Documents/Projects/vercel/ph-django-main/employee/views.py", line 89, in dispatch
    return super().dispatch(request, *args, **kwargs)
  File "/Users/sumith/Documents/Projects/vercel/phenv/lib/python3.9/site-packages/rest_framework/views.py", line 509, in dispatch
    response = self.handle_exception(exc)
  File "/Users/sumith/Documents/Projects/vercel/phenv/lib/python3.9/site-packages/rest_framework/views.py", line 463, in handle_exception
    exception_handler = self.get_exception_handler()
  File "/Users/sumith/Documents/Projects/vercel/phenv/lib/python3.9/site-packages/rest_framework/views.py", line 298, in get_exception_handler
    return self.settings.EXCEPTION_HANDLER
  File "/Users/sumith/Documents/Projects/vercel/phenv/lib/python3.9/site-packages/rest_framework/settings.py", line 225, in __getattr__
    val = perform_import(val, attr)
  File "/Users/sumith/Documents/Projects/vercel/phenv/lib/python3.9/site-packages/rest_framework/settings.py", line 166, in perform_import
    return import_from_string(val, setting_name)
  File "/Users/sumith/Documents/Projects/vercel/phenv/lib/python3.9/site-packages/rest_framework/settings.py", line 180, in import_from_string
    raise ImportError(msg)
ImportError: Could not import 'your_project_name.api.exceptions.custom_exception_handler' for API setting 'EXCEPTION_HANDLER'. ModuleNotFoundError: No module named 'your_project_name'.
2023-06-10 11:19:06 [ERROR] /Users/sumith/Documents/Projects/vercel/phenv/lib/python3.9/site-packages/django/utils/log.py:241 Internal Server Error: /signup/
Traceback (most recent call last):
  File "/Users/sumith/Documents/Projects/vercel/phenv/lib/python3.9/site-packages/rest_framework/views.py", line 497, in dispatch
    self.initial(request, *args, **kwargs)
  File "/Users/sumith/Documents/Projects/vercel/phenv/lib/python3.9/site-packages/rest_framework/views.py", line 414, in initial
    self.perform_authentication(request)
  File "/Users/sumith/Documents/Projects/vercel/phenv/lib/python3.9/site-packages/rest_framework/views.py", line 324, in perform_authentication
    request.user
  File "/Users/sumith/Documents/Projects/vercel/phenv/lib/python3.9/site-packages/rest_framework/request.py", line 227, in user
    self._authenticate()
  File "/Users/sumith/Documents/Projects/vercel/phenv/lib/python3.9/site-packages/rest_framework/request.py", line 380, in _authenticate
    user_auth_tuple = authenticator.authenticate(self)
  File "/Users/sumith/Documents/Projects/vercel/phenv/lib/python3.9/site-packages/rest_framework/authentication.py", line 130, in authenticate
    self.enforce_csrf(request)
  File "/Users/sumith/Documents/Projects/vercel/phenv/lib/python3.9/site-packages/rest_framework/authentication.py", line 148, in enforce_csrf
    raise exceptions.PermissionDenied('CSRF Failed: %s' % reason)
rest_framework.exceptions.PermissionDenied: CSRF Failed: CSRF token missing.

During handling of the above exception, another exception occurred:

Traceback (most recent call last):
  File "/Users/sumith/Documents/Projects/vercel/phenv/lib/python3.9/site-packages/rest_framework/settings.py", line 177, in import_from_string
    return import_string(val)
  File "/Users/sumith/Documents/Projects/vercel/phenv/lib/python3.9/site-packages/django/utils/module_loading.py", line 30, in import_string
    return cached_import(module_path, class_name)
  File "/Users/sumith/Documents/Projects/vercel/phenv/lib/python3.9/site-packages/django/utils/module_loading.py", line 15, in cached_import
    module = import_module(module_path)
  File "/Users/sumith/opt/anaconda3/lib/python3.9/importlib/__init__.py", line 127, in import_module
    return _bootstrap._gcd_import(name[level:], package, level)
  File "<frozen importlib._bootstrap>", line 1030, in _gcd_import
  File "<frozen importlib._bootstrap>", line 1007, in _find_and_load
  File "<frozen importlib._bootstrap>", line 972, in _find_and_load_unlocked
  File "<frozen importlib._bootstrap>", line 228, in _call_with_frames_removed
  File "<frozen importlib._bootstrap>", line 1030, in _gcd_import
  File "<frozen importlib._bootstrap>", line 1007, in _find_and_load
  File "<frozen importlib._bootstrap>", line 984, in _find_and_load_unlocked
ModuleNotFoundError: No module named 'vercel_app.api'

During handling of the above exception, another exception occurred:

Traceback (most recent call last):
  File "/Users/sumith/Documents/Projects/vercel/phenv/lib/python3.9/site-packages/django/core/handlers/exception.py", line 55, in inner
    response = get_response(request)
  File "/Users/sumith/Documents/Projects/vercel/phenv/lib/python3.9/site-packages/django/core/handlers/base.py", line 197, in _get_response
    response = wrapped_callback(request, *callback_args, **callback_kwargs)
  File "/Users/sumith/Documents/Projects/vercel/phenv/lib/python3.9/site-packages/django/views/decorators/csrf.py", line 56, in wrapper_view
    return view_func(*args, **kwargs)
  File "/Users/sumith/Documents/Projects/vercel/phenv/lib/python3.9/site-packages/django/views/generic/base.py", line 104, in view
    return self.dispatch(request, *args, **kwargs)
  File "/Users/sumith/Documents/Projects/vercel/phenv/lib/python3.9/site-packages/django/views/decorators/csrf.py", line 56, in wrapper_view
    return view_func(*args, **kwargs)
  File "/Users/sumith/Documents/Projects/vercel/ph-django-main/employee/views.py", line 89, in dispatch
    return super().dispatch(request, *args, **kwargs)
  File "/Users/sumith/Documents/Projects/vercel/phenv/lib/python3.9/site-packages/rest_framework/views.py", line 509, in dispatch
    response = self.handle_exception(exc)
  File "/Users/sumith/Documents/Projects/vercel/phenv/lib/python3.9/site-packages/rest_framework/views.py", line 463, in handle_exception
    exception_handler = self.get_exception_handler()
  File "/Users/sumith/Documents/Projects/vercel/phenv/lib/python3.9/site-packages/rest_framework/views.py", line 298, in get_exception_handler
    return self.settings.EXCEPTION_HANDLER
  File "/Users/sumith/Documents/Projects/vercel/phenv/lib/python3.9/site-packages/rest_framework/settings.py", line 225, in __getattr__
    val = perform_import(val, attr)
  File "/Users/sumith/Documents/Projects/vercel/phenv/lib/python3.9/site-packages/rest_framework/settings.py", line 166, in perform_import
    return import_from_string(val, setting_name)
  File "/Users/sumith/Documents/Projects/vercel/phenv/lib/python3.9/site-packages/rest_framework/settings.py", line 180, in import_from_string
    raise ImportError(msg)
ImportError: Could not import 'vercel_app.api.exceptions.custom_exception_handler' for API setting 'EXCEPTION_HANDLER'. ModuleNotFoundError: No module named 'vercel_app.api'.
2023-06-15 13:48:13 [ERROR] /Users/sumith/Documents/Projects/vercel/phenv/lib/python3.9/site-packages/django/utils/log.py:241 Internal Server Error: /api/testparagraphs/
Traceback (most recent call last):
  File "/Users/sumith/Documents/Projects/vercel/phenv/lib/python3.9/site-packages/django/db/backends/utils.py", line 89, in _execute
    return self.cursor.execute(sql, params)
psycopg2.errors.UndefinedTable: relation "test_paragraph" does not exist
LINE 1: INSERT INTO "test_paragraph" ("test_record_id", "para_ee", "...
                    ^


The above exception was the direct cause of the following exception:

Traceback (most recent call last):
  File "/Users/sumith/Documents/Projects/vercel/phenv/lib/python3.9/site-packages/django/core/handlers/exception.py", line 55, in inner
    response = get_response(request)
  File "/Users/sumith/Documents/Projects/vercel/phenv/lib/python3.9/site-packages/django/core/handlers/base.py", line 197, in _get_response
    response = wrapped_callback(request, *callback_args, **callback_kwargs)
  File "/Users/sumith/Documents/Projects/vercel/phenv/lib/python3.9/site-packages/django/views/decorators/csrf.py", line 56, in wrapper_view
    return view_func(*args, **kwargs)
  File "/Users/sumith/Documents/Projects/vercel/phenv/lib/python3.9/site-packages/rest_framework/viewsets.py", line 125, in view
    return self.dispatch(request, *args, **kwargs)
  File "/Users/sumith/Documents/Projects/vercel/phenv/lib/python3.9/site-packages/rest_framework/views.py", line 509, in dispatch
    response = self.handle_exception(exc)
  File "/Users/sumith/Documents/Projects/vercel/phenv/lib/python3.9/site-packages/rest_framework/views.py", line 469, in handle_exception
    self.raise_uncaught_exception(exc)
  File "/Users/sumith/Documents/Projects/vercel/phenv/lib/python3.9/site-packages/rest_framework/views.py", line 480, in raise_uncaught_exception
    raise exc
  File "/Users/sumith/Documents/Projects/vercel/phenv/lib/python3.9/site-packages/rest_framework/views.py", line 506, in dispatch
    response = handler(request, *args, **kwargs)
  File "/Users/sumith/Documents/Projects/vercel/ph-django-main/recommendations/views.py", line 14, in create
    self.perform_create(serializer)
  File "/Users/sumith/Documents/Projects/vercel/phenv/lib/python3.9/site-packages/rest_framework/mixins.py", line 24, in perform_create
    serializer.save()
  File "/Users/sumith/Documents/Projects/vercel/phenv/lib/python3.9/site-packages/rest_framework/serializers.py", line 212, in save
    self.instance = self.create(validated_data)
  File "/Users/sumith/Documents/Projects/vercel/phenv/lib/python3.9/site-packages/rest_framework/serializers.py", line 962, in create
    instance = ModelClass._default_manager.create(**validated_data)
  File "/Users/sumith/Documents/Projects/vercel/phenv/lib/python3.9/site-packages/django/db/models/manager.py", line 87, in manager_method
    return getattr(self.get_queryset(), name)(*args, **kwargs)
  File "/Users/sumith/Documents/Projects/vercel/phenv/lib/python3.9/site-packages/django/db/models/query.py", line 658, in create
    obj.save(force_insert=True, using=self.db)
  File "/Users/sumith/Documents/Projects/vercel/phenv/lib/python3.9/site-packages/django/db/models/base.py", line 814, in save
    self.save_base(
  File "/Users/sumith/Documents/Projects/vercel/phenv/lib/python3.9/site-packages/django/db/models/base.py", line 877, in save_base
    updated = self._save_table(
  File "/Users/sumith/Documents/Projects/vercel/phenv/lib/python3.9/site-packages/django/db/models/base.py", line 1020, in _save_table
    results = self._do_insert(
  File "/Users/sumith/Documents/Projects/vercel/phenv/lib/python3.9/site-packages/django/db/models/base.py", line 1061, in _do_insert
    return manager._insert(
  File "/Users/sumith/Documents/Projects/vercel/phenv/lib/python3.9/site-packages/django/db/models/manager.py", line 87, in manager_method
    return getattr(self.get_queryset(), name)(*args, **kwargs)
  File "/Users/sumith/Documents/Projects/vercel/phenv/lib/python3.9/site-packages/django/db/models/query.py", line 1805, in _insert
    return query.get_compiler(using=using).execute_sql(returning_fields)
  File "/Users/sumith/Documents/Projects/vercel/phenv/lib/python3.9/site-packages/django/db/models/sql/compiler.py", line 1820, in execute_sql
    cursor.execute(sql, params)
  File "/Users/sumith/Documents/Projects/vercel/phenv/lib/python3.9/site-packages/django/db/backends/utils.py", line 102, in execute
    return super().execute(sql, params)
  File "/Users/sumith/Documents/Projects/vercel/phenv/lib/python3.9/site-packages/django/db/backends/utils.py", line 67, in execute
    return self._execute_with_wrappers(
  File "/Users/sumith/Documents/Projects/vercel/phenv/lib/python3.9/site-packages/django/db/backends/utils.py", line 80, in _execute_with_wrappers
    return executor(sql, params, many, context)
  File "/Users/sumith/Documents/Projects/vercel/phenv/lib/python3.9/site-packages/django/db/backends/utils.py", line 89, in _execute
    return self.cursor.execute(sql, params)
  File "/Users/sumith/Documents/Projects/vercel/phenv/lib/python3.9/site-packages/django/db/utils.py", line 91, in __exit__
    raise dj_exc_value.with_traceback(traceback) from exc_value
  File "/Users/sumith/Documents/Projects/vercel/phenv/lib/python3.9/site-packages/django/db/backends/utils.py", line 89, in _execute
    return self.cursor.execute(sql, params)
django.db.utils.ProgrammingError: relation "test_paragraph" does not exist
LINE 1: INSERT INTO "test_paragraph" ("test_record_id", "para_ee", "...
                    ^

2023-06-15 15:02:20 [ERROR] /Users/sumith/Documents/Projects/vercel/phenv/lib/python3.9/site-packages/django/utils/log.py:241 Internal Server Error: /api/videorecommendations
Traceback (most recent call last):
  File "/Users/sumith/Documents/Projects/vercel/phenv/lib/python3.9/site-packages/django/core/handlers/exception.py", line 55, in inner
    response = get_response(request)
  File "/Users/sumith/Documents/Projects/vercel/phenv/lib/python3.9/site-packages/django/utils/deprecation.py", line 136, in __call__
    response = self.process_response(request, response)
  File "/Users/sumith/Documents/Projects/vercel/phenv/lib/python3.9/site-packages/django/middleware/common.py", line 108, in process_response
    return self.response_redirect_class(self.get_full_path_with_slash(request))
  File "/Users/sumith/Documents/Projects/vercel/phenv/lib/python3.9/site-packages/django/middleware/common.py", line 87, in get_full_path_with_slash
    raise RuntimeError(
RuntimeError: You called this URL via POST, but the URL doesn't end in a slash and you have APPEND_SLASH set. Django can't redirect to the slash URL while maintaining POST data. Change your form to point to localhost:8000/api/videorecommendations/ (note the trailing slash), or set APPEND_SLASH=False in your Django settings.
2023-06-20 07:34:30 [ERROR] /Users/sumith/Documents/Projects/vercel/phenv/lib/python3.9/site-packages/django/utils/log.py:241 Internal Server Error: /api/recommend/
Traceback (most recent call last):
  File "/Users/sumith/Documents/Projects/vercel/phenv/lib/python3.9/site-packages/django/core/handlers/exception.py", line 55, in inner
    response = get_response(request)
  File "/Users/sumith/Documents/Projects/vercel/phenv/lib/python3.9/site-packages/django/core/handlers/base.py", line 197, in _get_response
    response = wrapped_callback(request, *callback_args, **callback_kwargs)
  File "/Users/sumith/Documents/Projects/vercel/phenv/lib/python3.9/site-packages/django/views/decorators/csrf.py", line 56, in wrapper_view
    return view_func(*args, **kwargs)
  File "/Users/sumith/Documents/Projects/vercel/ph-django-main/recommendations/views.py", line 255, in recommend_videos
    json_data = json.loads(data)
NameError: name 'json' is not defined
2023-06-20 08:02:41 [ERROR] /Users/sumith/Documents/Projects/vercel/phenv/lib/python3.9/site-packages/django/utils/log.py:241 Internal Server Error: /api/recommend/
Traceback (most recent call last):
  File "/Users/sumith/Documents/Projects/vercel/phenv/lib/python3.9/site-packages/django/core/handlers/exception.py", line 55, in inner
    response = get_response(request)
  File "/Users/sumith/Documents/Projects/vercel/phenv/lib/python3.9/site-packages/django/core/handlers/base.py", line 197, in _get_response
    response = wrapped_callback(request, *callback_args, **callback_kwargs)
  File "/Users/sumith/Documents/Projects/vercel/phenv/lib/python3.9/site-packages/django/views/decorators/csrf.py", line 56, in wrapper_view
    return view_func(*args, **kwargs)
  File "/Users/sumith/Documents/Projects/vercel/ph-django-main/recommendations/views.py", line 278, in recommend_videos
    similarity_scores = calculate_similarity_bert(query_embeddings, corpus_embeddings)
  File "/Users/sumith/Documents/Projects/vercel/ph-django-main/recommendations/views.py", line 257, in calculate_similarity_bert
    similarity_scores = cosine_similarity([query_embedding], corpus_embeddings)[0]
  File "/Users/sumith/Documents/Projects/vercel/phenv/lib/python3.9/site-packages/sklearn/metrics/pairwise.py", line 1393, in cosine_similarity
    X, Y = check_pairwise_arrays(X, Y)
  File "/Users/sumith/Documents/Projects/vercel/phenv/lib/python3.9/site-packages/sklearn/metrics/pairwise.py", line 155, in check_pairwise_arrays
    X = check_array(
  File "/Users/sumith/Documents/Projects/vercel/phenv/lib/python3.9/site-packages/sklearn/utils/validation.py", line 915, in check_array
    raise ValueError(
ValueError: Found array with dim 3. check_pairwise_arrays expected <= 2.
2023-06-20 08:22:28 [ERROR] /Users/sumith/Documents/Projects/vercel/phenv/lib/python3.9/site-packages/django/utils/log.py:241 Internal Server Error: /api/recommend/
Traceback (most recent call last):
  File "/Users/sumith/Documents/Projects/vercel/phenv/lib/python3.9/site-packages/django/core/handlers/exception.py", line 55, in inner
    response = get_response(request)
  File "/Users/sumith/Documents/Projects/vercel/phenv/lib/python3.9/site-packages/django/core/handlers/base.py", line 197, in _get_response
    response = wrapped_callback(request, *callback_args, **callback_kwargs)
  File "/Users/sumith/Documents/Projects/vercel/phenv/lib/python3.9/site-packages/django/views/decorators/csrf.py", line 56, in wrapper_view
    return view_func(*args, **kwargs)
  File "/Users/sumith/Documents/Projects/vercel/ph-django-main/recommendations/views.py", line 303, in recommend_videos
    level = eval(paragraph + "_level")
  File "<string>", line 1, in <module>
NameError: name 'ee_llm_level' is not defined
2023-06-20 08:28:21 [ERROR] /Users/sumith/Documents/Projects/vercel/phenv/lib/python3.9/site-packages/django/utils/log.py:241 Internal Server Error: /api/recommend/
Traceback (most recent call last):
  File "/Users/sumith/Documents/Projects/vercel/phenv/lib/python3.9/site-packages/django/core/handlers/exception.py", line 55, in inner
    response = get_response(request)
  File "/Users/sumith/Documents/Projects/vercel/phenv/lib/python3.9/site-packages/django/core/handlers/base.py", line 197, in _get_response
    response = wrapped_callback(request, *callback_args, **callback_kwargs)
  File "/Users/sumith/Documents/Projects/vercel/phenv/lib/python3.9/site-packages/django/views/decorators/csrf.py", line 56, in wrapper_view
    return view_func(*args, **kwargs)
  File "/Users/sumith/Documents/Projects/vercel/ph-django-main/recommendations/views.py", line 314, in recommend_videos
    return JsonResponse(result, safe=False)
  File "/Users/sumith/Documents/Projects/vercel/phenv/lib/python3.9/site-packages/django/http/response.py", line 731, in __init__
    data = json.dumps(data, cls=encoder, **json_dumps_params)
  File "/Users/sumith/opt/anaconda3/lib/python3.9/json/__init__.py", line 234, in dumps
    return cls(
  File "/Users/sumith/opt/anaconda3/lib/python3.9/json/encoder.py", line 199, in encode
    chunks = self.iterencode(o, _one_shot=True)
  File "/Users/sumith/opt/anaconda3/lib/python3.9/json/encoder.py", line 257, in iterencode
    return _iterencode(o, 0)
  File "/Users/sumith/Documents/Projects/vercel/phenv/lib/python3.9/site-packages/django/core/serializers/json.py", line 106, in default
    return super().default(o)
  File "/Users/sumith/opt/anaconda3/lib/python3.9/json/encoder.py", line 179, in default
    raise TypeError(f'Object of type {o.__class__.__name__} '
TypeError: Object of type DataFrame is not JSON serializable
2023-06-20 08:45:45 [ERROR] /Users/sumith/Documents/Projects/vercel/phenv/lib/python3.9/site-packages/django/utils/log.py:241 Internal Server Error: /api/recommend/
Traceback (most recent call last):
  File "/Users/sumith/Documents/Projects/vercel/phenv/lib/python3.9/site-packages/django/core/handlers/exception.py", line 55, in inner
    response = get_response(request)
  File "/Users/sumith/Documents/Projects/vercel/phenv/lib/python3.9/site-packages/django/core/handlers/base.py", line 197, in _get_response
    response = wrapped_callback(request, *callback_args, **callback_kwargs)
  File "/Users/sumith/Documents/Projects/vercel/phenv/lib/python3.9/site-packages/django/views/decorators/csrf.py", line 56, in wrapper_view
    return view_func(*args, **kwargs)
  File "/Users/sumith/Documents/Projects/vercel/ph-django-main/recommendations/views.py", line 313, in recommend_videos
    query = result[paragraph]
KeyError: 'ee_llm'
2023-06-20 08:55:50 [ERROR] /Users/sumith/Documents/Projects/vercel/phenv/lib/python3.9/site-packages/django/utils/log.py:241 Internal Server Error: /api/recommend/
Traceback (most recent call last):
  File "/Users/sumith/Documents/Projects/vercel/phenv/lib/python3.9/site-packages/django/core/handlers/exception.py", line 55, in inner
    response = get_response(request)
  File "/Users/sumith/Documents/Projects/vercel/phenv/lib/python3.9/site-packages/django/core/handlers/base.py", line 197, in _get_response
    response = wrapped_callback(request, *callback_args, **callback_kwargs)
  File "/Users/sumith/Documents/Projects/vercel/phenv/lib/python3.9/site-packages/django/views/decorators/csrf.py", line 56, in wrapper_view
    return view_func(*args, **kwargs)
  File "/Users/sumith/Documents/Projects/vercel/ph-django-main/recommendations/views.py", line 344, in recommend_videos
    return JsonResponse(result, safe=False)
  File "/Users/sumith/Documents/Projects/vercel/phenv/lib/python3.9/site-packages/django/http/response.py", line 731, in __init__
    data = json.dumps(data, cls=encoder, **json_dumps_params)
  File "/Users/sumith/opt/anaconda3/lib/python3.9/json/__init__.py", line 234, in dumps
    return cls(
  File "/Users/sumith/opt/anaconda3/lib/python3.9/json/encoder.py", line 199, in encode
    chunks = self.iterencode(o, _one_shot=True)
  File "/Users/sumith/opt/anaconda3/lib/python3.9/json/encoder.py", line 257, in iterencode
    return _iterencode(o, 0)
  File "/Users/sumith/Documents/Projects/vercel/phenv/lib/python3.9/site-packages/django/core/serializers/json.py", line 106, in default
    return super().default(o)
  File "/Users/sumith/opt/anaconda3/lib/python3.9/json/encoder.py", line 179, in default
    raise TypeError(f'Object of type {o.__class__.__name__} '
TypeError: Object of type float32 is not JSON serializable
2023-06-20 19:48:47 [ERROR] /Users/sumith/Documents/Projects/vercel/phenv/lib/python3.9/site-packages/django/utils/log.py:241 Internal Server Error: /api/testparagraphs/
Traceback (most recent call last):
  File "/Users/sumith/Documents/Projects/vercel/phenv/lib/python3.9/site-packages/django/core/handlers/exception.py", line 55, in inner
    response = get_response(request)
  File "/Users/sumith/Documents/Projects/vercel/phenv/lib/python3.9/site-packages/django/core/handlers/base.py", line 197, in _get_response
    response = wrapped_callback(request, *callback_args, **callback_kwargs)
  File "/Users/sumith/Documents/Projects/vercel/phenv/lib/python3.9/site-packages/django/views/decorators/csrf.py", line 56, in wrapper_view
    return view_func(*args, **kwargs)
  File "/Users/sumith/Documents/Projects/vercel/phenv/lib/python3.9/site-packages/rest_framework/viewsets.py", line 125, in view
    return self.dispatch(request, *args, **kwargs)
  File "/Users/sumith/Documents/Projects/vercel/phenv/lib/python3.9/site-packages/rest_framework/views.py", line 509, in dispatch
    response = self.handle_exception(exc)
  File "/Users/sumith/Documents/Projects/vercel/phenv/lib/python3.9/site-packages/rest_framework/views.py", line 469, in handle_exception
    self.raise_uncaught_exception(exc)
  File "/Users/sumith/Documents/Projects/vercel/phenv/lib/python3.9/site-packages/rest_framework/views.py", line 480, in raise_uncaught_exception
    raise exc
  File "/Users/sumith/Documents/Projects/vercel/phenv/lib/python3.9/site-packages/rest_framework/views.py", line 506, in dispatch
    response = handler(request, *args, **kwargs)
  File "/Users/sumith/Documents/Projects/vercel/ph-django-main/recommendations/views.py", line 15, in create
    json_data = json.loads(request.data)
  File "/Users/sumith/opt/anaconda3/lib/python3.9/json/__init__.py", line 339, in loads
    raise TypeError(f'the JSON object must be str, bytes or bytearray, '
TypeError: the JSON object must be str, bytes or bytearray, not dict
2023-06-20 19:54:22 [ERROR] /Users/sumith/Documents/Projects/vercel/phenv/lib/python3.9/site-packages/django/utils/log.py:241 Internal Server Error: /api/testparagraphs/
Traceback (most recent call last):
  File "/Users/sumith/Documents/Projects/vercel/phenv/lib/python3.9/site-packages/django/core/handlers/exception.py", line 55, in inner
    response = get_response(request)
  File "/Users/sumith/Documents/Projects/vercel/phenv/lib/python3.9/site-packages/django/core/handlers/base.py", line 197, in _get_response
    response = wrapped_callback(request, *callback_args, **callback_kwargs)
  File "/Users/sumith/Documents/Projects/vercel/phenv/lib/python3.9/site-packages/django/views/decorators/csrf.py", line 56, in wrapper_view
    return view_func(*args, **kwargs)
  File "/Users/sumith/Documents/Projects/vercel/phenv/lib/python3.9/site-packages/rest_framework/viewsets.py", line 125, in view
    return self.dispatch(request, *args, **kwargs)
  File "/Users/sumith/Documents/Projects/vercel/phenv/lib/python3.9/site-packages/rest_framework/views.py", line 509, in dispatch
    response = self.handle_exception(exc)
  File "/Users/sumith/Documents/Projects/vercel/phenv/lib/python3.9/site-packages/rest_framework/views.py", line 469, in handle_exception
    self.raise_uncaught_exception(exc)
  File "/Users/sumith/Documents/Projects/vercel/phenv/lib/python3.9/site-packages/rest_framework/views.py", line 480, in raise_uncaught_exception
    raise exc
  File "/Users/sumith/Documents/Projects/vercel/phenv/lib/python3.9/site-packages/rest_framework/views.py", line 506, in dispatch
    response = handler(request, *args, **kwargs)
  File "/Users/sumith/Documents/Projects/vercel/ph-django-main/recommendations/views.py", line 17, in create
    serializer = self.get_serializer(data=request.data)
NameError: name 'json_data' is not defined
2023-06-21 06:17:28 [ERROR] /Users/sumith/Documents/Projects/vercel/phenv/lib/python3.9/site-packages/django/utils/log.py:241 Internal Server Error: /api/testparagraphs/
Traceback (most recent call last):
  File "/Users/sumith/Documents/Projects/vercel/phenv/lib/python3.9/site-packages/django/db/models/fields/__init__.py", line 2055, in get_prep_value
    return int(value)
ValueError: invalid literal for int() with base 10: '7c6a4774-e244-4098-8416-438c63ceac6d'

The above exception was the direct cause of the following exception:

Traceback (most recent call last):
  File "/Users/sumith/Documents/Projects/vercel/phenv/lib/python3.9/site-packages/django/core/handlers/exception.py", line 55, in inner
    response = get_response(request)
  File "/Users/sumith/Documents/Projects/vercel/phenv/lib/python3.9/site-packages/django/core/handlers/base.py", line 197, in _get_response
    response = wrapped_callback(request, *callback_args, **callback_kwargs)
  File "/Users/sumith/Documents/Projects/vercel/phenv/lib/python3.9/site-packages/django/views/decorators/csrf.py", line 56, in wrapper_view
    return view_func(*args, **kwargs)
  File "/Users/sumith/Documents/Projects/vercel/phenv/lib/python3.9/site-packages/rest_framework/viewsets.py", line 125, in view
    return self.dispatch(request, *args, **kwargs)
  File "/Users/sumith/Documents/Projects/vercel/phenv/lib/python3.9/site-packages/rest_framework/views.py", line 509, in dispatch
    response = self.handle_exception(exc)
  File "/Users/sumith/Documents/Projects/vercel/phenv/lib/python3.9/site-packages/rest_framework/views.py", line 469, in handle_exception
    self.raise_uncaught_exception(exc)
  File "/Users/sumith/Documents/Projects/vercel/phenv/lib/python3.9/site-packages/rest_framework/views.py", line 480, in raise_uncaught_exception
    raise exc
  File "/Users/sumith/Documents/Projects/vercel/phenv/lib/python3.9/site-packages/rest_framework/views.py", line 506, in dispatch
    response = handler(request, *args, **kwargs)
  File "/Users/sumith/Documents/Projects/vercel/ph-django-main/recommendations/views.py", line 44, in create
    test_record = TestRecord.objects.get(pk=test_record_pk)
  File "/Users/sumith/Documents/Projects/vercel/phenv/lib/python3.9/site-packages/django/db/models/manager.py", line 87, in manager_method
    return getattr(self.get_queryset(), name)(*args, **kwargs)
  File "/Users/sumith/Documents/Projects/vercel/phenv/lib/python3.9/site-packages/django/db/models/query.py", line 623, in get
    clone = self._chain() if self.query.combinator else self.filter(*args, **kwargs)
  File "/Users/sumith/Documents/Projects/vercel/phenv/lib/python3.9/site-packages/django/db/models/query.py", line 1436, in filter
    return self._filter_or_exclude(False, args, kwargs)
  File "/Users/sumith/Documents/Projects/vercel/phenv/lib/python3.9/site-packages/django/db/models/query.py", line 1454, in _filter_or_exclude
    clone._filter_or_exclude_inplace(negate, args, kwargs)
  File "/Users/sumith/Documents/Projects/vercel/phenv/lib/python3.9/site-packages/django/db/models/query.py", line 1461, in _filter_or_exclude_inplace
    self._query.add_q(Q(*args, **kwargs))
  File "/Users/sumith/Documents/Projects/vercel/phenv/lib/python3.9/site-packages/django/db/models/sql/query.py", line 1502, in add_q
    clause, _ = self._add_q(q_object, self.used_aliases)
  File "/Users/sumith/Documents/Projects/vercel/phenv/lib/python3.9/site-packages/django/db/models/sql/query.py", line 1533, in _add_q
    child_clause, needed_inner = self.build_filter(
  File "/Users/sumith/Documents/Projects/vercel/phenv/lib/python3.9/site-packages/django/db/models/sql/query.py", line 1448, in build_filter
    condition = self.build_lookup(lookups, col, value)
  File "/Users/sumith/Documents/Projects/vercel/phenv/lib/python3.9/site-packages/django/db/models/sql/query.py", line 1275, in build_lookup
    lookup = lookup_class(lhs, rhs)
  File "/Users/sumith/Documents/Projects/vercel/phenv/lib/python3.9/site-packages/django/db/models/lookups.py", line 27, in __init__
    self.rhs = self.get_prep_lookup()
  File "/Users/sumith/Documents/Projects/vercel/phenv/lib/python3.9/site-packages/django/db/models/lookups.py", line 341, in get_prep_lookup
    return super().get_prep_lookup()
  File "/Users/sumith/Documents/Projects/vercel/phenv/lib/python3.9/site-packages/django/db/models/lookups.py", line 85, in get_prep_lookup
    return self.lhs.output_field.get_prep_value(self.rhs)
  File "/Users/sumith/Documents/Projects/vercel/phenv/lib/python3.9/site-packages/django/db/models/fields/__init__.py", line 2057, in get_prep_value
    raise e.__class__(
ValueError: Field 'id' expected a number but got '7c6a4774-e244-4098-8416-438c63ceac6d'.
2023-06-21 07:27:02 [ERROR] /Users/sumith/Documents/Projects/vercel/phenv/lib/python3.9/site-packages/django/utils/log.py:241 Internal Server Error: /api/testparagraphs/
Traceback (most recent call last):
  File "/Users/sumith/Documents/Projects/vercel/phenv/lib/python3.9/site-packages/langchain/llms/openai.py", line 243, in validate_environment
    import openai
ModuleNotFoundError: No module named 'openai'

During handling of the above exception, another exception occurred:

Traceback (most recent call last):
  File "/Users/sumith/Documents/Projects/vercel/phenv/lib/python3.9/site-packages/django/core/handlers/exception.py", line 55, in inner
    response = get_response(request)
  File "/Users/sumith/Documents/Projects/vercel/phenv/lib/python3.9/site-packages/django/core/handlers/base.py", line 197, in _get_response
    response = wrapped_callback(request, *callback_args, **callback_kwargs)
  File "/Users/sumith/Documents/Projects/vercel/phenv/lib/python3.9/site-packages/django/views/decorators/csrf.py", line 56, in wrapper_view
    return view_func(*args, **kwargs)
  File "/Users/sumith/Documents/Projects/vercel/phenv/lib/python3.9/site-packages/rest_framework/viewsets.py", line 125, in view
    return self.dispatch(request, *args, **kwargs)
  File "/Users/sumith/Documents/Projects/vercel/phenv/lib/python3.9/site-packages/rest_framework/views.py", line 509, in dispatch
    response = self.handle_exception(exc)
  File "/Users/sumith/Documents/Projects/vercel/phenv/lib/python3.9/site-packages/rest_framework/views.py", line 469, in handle_exception
    self.raise_uncaught_exception(exc)
  File "/Users/sumith/Documents/Projects/vercel/phenv/lib/python3.9/site-packages/rest_framework/views.py", line 480, in raise_uncaught_exception
    raise exc
  File "/Users/sumith/Documents/Projects/vercel/phenv/lib/python3.9/site-packages/rest_framework/views.py", line 506, in dispatch
    response = handler(request, *args, **kwargs)
  File "/Users/sumith/Documents/Projects/vercel/ph-django-main/recommendations/views.py", line 39, in create
    llm = OpenAI(openai_api_key=api_key, temperature=0.75)
  File "/Users/sumith/Documents/Projects/vercel/phenv/lib/python3.9/site-packages/langchain/load/serializable.py", line 64, in __init__
    super().__init__(**kwargs)
  File "pydantic/main.py", line 339, in pydantic.main.BaseModel.__init__
  File "pydantic/main.py", line 1102, in pydantic.main.validate_model
  File "/Users/sumith/Documents/Projects/vercel/phenv/lib/python3.9/site-packages/langchain/llms/openai.py", line 247, in validate_environment
    raise ImportError(
ImportError: Could not import openai python package. Please install it with `pip install openai`.
2023-06-21 07:36:30 [ERROR] /Users/sumith/Documents/Projects/vercel/phenv/lib/python3.9/site-packages/django/utils/log.py:241 Internal Server Error: /api/testparagraphs/
Traceback (most recent call last):
  File "/Users/sumith/Documents/Projects/vercel/phenv/lib/python3.9/site-packages/rest_framework/views.py", line 506, in dispatch
    response = handler(request, *args, **kwargs)
  File "/Users/sumith/Documents/Projects/vercel/ph-django-main/recommendations/views.py", line 47, in create
    TestParagraph.objects.create(test_record=test_record, paragraph=paragraph, response=response)
  File "/Users/sumith/Documents/Projects/vercel/phenv/lib/python3.9/site-packages/django/db/models/manager.py", line 87, in manager_method
    return getattr(self.get_queryset(), name)(*args, **kwargs)
  File "/Users/sumith/Documents/Projects/vercel/phenv/lib/python3.9/site-packages/django/db/models/query.py", line 656, in create
    obj = self.model(**kwargs)
  File "/Users/sumith/Documents/Projects/vercel/phenv/lib/python3.9/site-packages/django/db/models/base.py", line 567, in __init__
    raise TypeError(
TypeError: TestParagraph() got unexpected keyword arguments: 'paragraph', 'response'

During handling of the above exception, another exception occurred:

Traceback (most recent call last):
  File "/Users/sumith/Documents/Projects/vercel/phenv/lib/python3.9/site-packages/django/core/handlers/exception.py", line 55, in inner
    response = get_response(request)
  File "/Users/sumith/Documents/Projects/vercel/phenv/lib/python3.9/site-packages/django/core/handlers/base.py", line 197, in _get_response
    response = wrapped_callback(request, *callback_args, **callback_kwargs)
  File "/Users/sumith/Documents/Projects/vercel/phenv/lib/python3.9/site-packages/django/views/decorators/csrf.py", line 56, in wrapper_view
    return view_func(*args, **kwargs)
  File "/Users/sumith/Documents/Projects/vercel/phenv/lib/python3.9/site-packages/rest_framework/viewsets.py", line 125, in view
    return self.dispatch(request, *args, **kwargs)
  File "/Users/sumith/Documents/Projects/vercel/phenv/lib/python3.9/site-packages/rest_framework/views.py", line 509, in dispatch
    response = self.handle_exception(exc)
  File "/Users/sumith/Documents/Projects/vercel/ph-django-main/recommendations/views.py", line 58, in handle_exception
    if isinstance(exc, serializers.ValidationError):
NameError: name 'serializers' is not defined
2023-06-21 07:38:17 [ERROR] /Users/sumith/Documents/Projects/vercel/phenv/lib/python3.9/site-packages/django/utils/log.py:241 Internal Server Error: /api/testparagraphs/
Traceback (most recent call last):
  File "/Users/sumith/Documents/Projects/vercel/phenv/lib/python3.9/site-packages/django/core/handlers/exception.py", line 55, in inner
    response = get_response(request)
  File "/Users/sumith/Documents/Projects/vercel/phenv/lib/python3.9/site-packages/django/core/handlers/base.py", line 197, in _get_response
    response = wrapped_callback(request, *callback_args, **callback_kwargs)
  File "/Users/sumith/Documents/Projects/vercel/phenv/lib/python3.9/site-packages/django/views/decorators/csrf.py", line 56, in wrapper_view
    return view_func(*args, **kwargs)
  File "/Users/sumith/Documents/Projects/vercel/phenv/lib/python3.9/site-packages/rest_framework/viewsets.py", line 125, in view
    return self.dispatch(request, *args, **kwargs)
  File "/Users/sumith/Documents/Projects/vercel/phenv/lib/python3.9/site-packages/rest_framework/views.py", line 509, in dispatch
    response = self.handle_exception(exc)
  File "/Users/sumith/Documents/Projects/vercel/ph-django-main/recommendations/views.py", line 61, in handle_exception
    return super().handle_exception(exc)
  File "/Users/sumith/Documents/Projects/vercel/phenv/lib/python3.9/site-packages/rest_framework/views.py", line 469, in handle_exception
    self.raise_uncaught_exception(exc)
  File "/Users/sumith/Documents/Projects/vercel/phenv/lib/python3.9/site-packages/rest_framework/views.py", line 480, in raise_uncaught_exception
    raise exc
  File "/Users/sumith/Documents/Projects/vercel/phenv/lib/python3.9/site-packages/rest_framework/views.py", line 506, in dispatch
    response = handler(request, *args, **kwargs)
  File "/Users/sumith/Documents/Projects/vercel/ph-django-main/recommendations/views.py", line 47, in create
    TestParagraph.objects.create(test_record=test_record, paragraph=paragraph, response=response)
  File "/Users/sumith/Documents/Projects/vercel/phenv/lib/python3.9/site-packages/django/db/models/manager.py", line 87, in manager_method
    return getattr(self.get_queryset(), name)(*args, **kwargs)
  File "/Users/sumith/Documents/Projects/vercel/phenv/lib/python3.9/site-packages/django/db/models/query.py", line 656, in create
    obj = self.model(**kwargs)
  File "/Users/sumith/Documents/Projects/vercel/phenv/lib/python3.9/site-packages/django/db/models/base.py", line 567, in __init__
    raise TypeError(
TypeError: TestParagraph() got unexpected keyword arguments: 'paragraph', 'response'
2023-06-21 07:53:46 [ERROR] /Users/sumith/Documents/Projects/vercel/phenv/lib/python3.9/site-packages/django/utils/log.py:241 Internal Server Error: /api/testparagraphs/
Traceback (most recent call last):
  File "/Users/sumith/Documents/Projects/vercel/phenv/lib/python3.9/site-packages/django/core/handlers/exception.py", line 55, in inner
    response = get_response(request)
  File "/Users/sumith/Documents/Projects/vercel/phenv/lib/python3.9/site-packages/django/core/handlers/base.py", line 197, in _get_response
    response = wrapped_callback(request, *callback_args, **callback_kwargs)
  File "/Users/sumith/Documents/Projects/vercel/phenv/lib/python3.9/site-packages/django/views/decorators/csrf.py", line 56, in wrapper_view
    return view_func(*args, **kwargs)
  File "/Users/sumith/Documents/Projects/vercel/phenv/lib/python3.9/site-packages/rest_framework/viewsets.py", line 125, in view
    return self.dispatch(request, *args, **kwargs)
  File "/Users/sumith/Documents/Projects/vercel/phenv/lib/python3.9/site-packages/rest_framework/views.py", line 509, in dispatch
    response = self.handle_exception(exc)
  File "/Users/sumith/Documents/Projects/vercel/ph-django-main/recommendations/views.py", line 84, in handle_exception
    return Response(errors, status=status.HTTP_400_BAD_REQUEST)
  File "/Users/sumith/Documents/Projects/vercel/phenv/lib/python3.9/site-packages/rest_framework/views.py", line 469, in handle_exception
    self.raise_uncaught_exception(exc)
  File "/Users/sumith/Documents/Projects/vercel/phenv/lib/python3.9/site-packages/rest_framework/views.py", line 480, in raise_uncaught_exception
    raise exc
  File "/Users/sumith/Documents/Projects/vercel/phenv/lib/python3.9/site-packages/rest_framework/views.py", line 506, in dispatch
    response = handler(request, *args, **kwargs)
  File "/Users/sumith/Documents/Projects/vercel/ph-django-main/recommendations/views.py", line 35, in create
    print(para_dp)
NameError: name 'pa' is not defined
2023-06-22 08:05:32 [ERROR] /Users/sumith/Documents/Projects/vercel/phenv/lib/python3.9/site-packages/django/utils/log.py:241 Internal Server Error: /api/testparagraphs/
Traceback (most recent call last):
  File "/Users/sumith/Documents/Projects/vercel/phenv/lib/python3.9/site-packages/django/core/handlers/exception.py", line 55, in inner
    response = get_response(request)
  File "/Users/sumith/Documents/Projects/vercel/phenv/lib/python3.9/site-packages/django/core/handlers/base.py", line 197, in _get_response
    response = wrapped_callback(request, *callback_args, **callback_kwargs)
  File "/Users/sumith/Documents/Projects/vercel/phenv/lib/python3.9/site-packages/django/views/decorators/csrf.py", line 56, in wrapper_view
    return view_func(*args, **kwargs)
  File "/Users/sumith/Documents/Projects/vercel/phenv/lib/python3.9/site-packages/rest_framework/viewsets.py", line 125, in view
    return self.dispatch(request, *args, **kwargs)
  File "/Users/sumith/Documents/Projects/vercel/phenv/lib/python3.9/site-packages/rest_framework/views.py", line 509, in dispatch
    response = self.handle_exception(exc)
  File "/Users/sumith/Documents/Projects/vercel/ph-django-main/recommendations/views.py", line 107, in handle_exception
    return super().handle_exception(exc)
  File "/Users/sumith/Documents/Projects/vercel/phenv/lib/python3.9/site-packages/rest_framework/views.py", line 469, in handle_exception
    self.raise_uncaught_exception(exc)
  File "/Users/sumith/Documents/Projects/vercel/phenv/lib/python3.9/site-packages/rest_framework/views.py", line 480, in raise_uncaught_exception
    raise exc
  File "/Users/sumith/Documents/Projects/vercel/phenv/lib/python3.9/site-packages/rest_framework/views.py", line 506, in dispatch
    response = handler(request, *args, **kwargs)
  File "/Users/sumith/Documents/Projects/vercel/ph-django-main/recommendations/views.py", line 35, in create
    test_paragraph = TestParagraph.objects.get(test_record=test_record_id)
  File "/Users/sumith/Documents/Projects/vercel/phenv/lib/python3.9/site-packages/django/db/models/manager.py", line 87, in manager_method
    return getattr(self.get_queryset(), name)(*args, **kwargs)
  File "/Users/sumith/Documents/Projects/vercel/phenv/lib/python3.9/site-packages/django/db/models/query.py", line 640, in get
    raise self.model.MultipleObjectsReturned(
recommendations.models.TestParagraph.MultipleObjectsReturned: get() returned more than one TestParagraph -- it returned 2!
2023-06-22 08:09:56 [ERROR] /Users/sumith/Documents/Projects/vercel/phenv/lib/python3.9/site-packages/django/utils/log.py:241 Internal Server Error: /api/testparagraphs/
Traceback (most recent call last):
  File "/Users/sumith/Documents/Projects/vercel/phenv/lib/python3.9/site-packages/django/core/handlers/exception.py", line 55, in inner
    response = get_response(request)
  File "/Users/sumith/Documents/Projects/vercel/phenv/lib/python3.9/site-packages/django/core/handlers/base.py", line 197, in _get_response
    response = wrapped_callback(request, *callback_args, **callback_kwargs)
  File "/Users/sumith/Documents/Projects/vercel/phenv/lib/python3.9/site-packages/django/views/decorators/csrf.py", line 56, in wrapper_view
    return view_func(*args, **kwargs)
  File "/Users/sumith/Documents/Projects/vercel/phenv/lib/python3.9/site-packages/rest_framework/viewsets.py", line 125, in view
    return self.dispatch(request, *args, **kwargs)
  File "/Users/sumith/Documents/Projects/vercel/phenv/lib/python3.9/site-packages/rest_framework/views.py", line 509, in dispatch
    response = self.handle_exception(exc)
  File "/Users/sumith/Documents/Projects/vercel/ph-django-main/recommendations/views.py", line 107, in handle_exception
    return super().handle_exception(exc)
  File "/Users/sumith/Documents/Projects/vercel/phenv/lib/python3.9/site-packages/rest_framework/views.py", line 469, in handle_exception
    self.raise_uncaught_exception(exc)
  File "/Users/sumith/Documents/Projects/vercel/phenv/lib/python3.9/site-packages/rest_framework/views.py", line 480, in raise_uncaught_exception
    raise exc
  File "/Users/sumith/Documents/Projects/vercel/phenv/lib/python3.9/site-packages/rest_framework/views.py", line 506, in dispatch
    response = handler(request, *args, **kwargs)
  File "/Users/sumith/Documents/Projects/vercel/ph-django-main/recommendations/views.py", line 35, in create
    test_paragraph = TestParagraph.objects.get(test_record=test_record_id)
  File "/Users/sumith/Documents/Projects/vercel/phenv/lib/python3.9/site-packages/django/db/models/manager.py", line 87, in manager_method
    return getattr(self.get_queryset(), name)(*args, **kwargs)
  File "/Users/sumith/Documents/Projects/vercel/phenv/lib/python3.9/site-packages/django/db/models/query.py", line 640, in get
    raise self.model.MultipleObjectsReturned(
recommendations.models.TestParagraph.MultipleObjectsReturned: get() returned more than one TestParagraph -- it returned 2!
2023-06-22 08:10:37 [ERROR] /Users/sumith/Documents/Projects/vercel/phenv/lib/python3.9/site-packages/django/utils/log.py:241 Internal Server Error: /api/testparagraphs/
Traceback (most recent call last):
  File "/Users/sumith/Documents/Projects/vercel/phenv/lib/python3.9/site-packages/django/core/handlers/exception.py", line 55, in inner
    response = get_response(request)
  File "/Users/sumith/Documents/Projects/vercel/phenv/lib/python3.9/site-packages/django/core/handlers/base.py", line 197, in _get_response
    response = wrapped_callback(request, *callback_args, **callback_kwargs)
  File "/Users/sumith/Documents/Projects/vercel/phenv/lib/python3.9/site-packages/django/views/decorators/csrf.py", line 56, in wrapper_view
    return view_func(*args, **kwargs)
  File "/Users/sumith/Documents/Projects/vercel/phenv/lib/python3.9/site-packages/rest_framework/viewsets.py", line 125, in view
    return self.dispatch(request, *args, **kwargs)
  File "/Users/sumith/Documents/Projects/vercel/phenv/lib/python3.9/site-packages/rest_framework/views.py", line 509, in dispatch
    response = self.handle_exception(exc)
  File "/Users/sumith/Documents/Projects/vercel/ph-django-main/recommendations/views.py", line 107, in handle_exception
    return super().handle_exception(exc)
  File "/Users/sumith/Documents/Projects/vercel/phenv/lib/python3.9/site-packages/rest_framework/views.py", line 469, in handle_exception
    self.raise_uncaught_exception(exc)
  File "/Users/sumith/Documents/Projects/vercel/phenv/lib/python3.9/site-packages/rest_framework/views.py", line 480, in raise_uncaught_exception
    raise exc
  File "/Users/sumith/Documents/Projects/vercel/phenv/lib/python3.9/site-packages/rest_framework/views.py", line 506, in dispatch
    response = handler(request, *args, **kwargs)
  File "/Users/sumith/Documents/Projects/vercel/ph-django-main/recommendations/views.py", line 35, in create
    test_paragraph = TestParagraph.objects.get(test_record=test_record_id)
  File "/Users/sumith/Documents/Projects/vercel/phenv/lib/python3.9/site-packages/django/db/models/manager.py", line 87, in manager_method
    return getattr(self.get_queryset(), name)(*args, **kwargs)
  File "/Users/sumith/Documents/Projects/vercel/phenv/lib/python3.9/site-packages/django/db/models/query.py", line 640, in get
    raise self.model.MultipleObjectsReturned(
recommendations.models.TestParagraph.MultipleObjectsReturned: get() returned more than one TestParagraph -- it returned 2!
2023-06-22 11:06:03 [ERROR] /Users/sumith/Documents/Projects/vercel/phenv/lib/python3.9/site-packages/django/utils/log.py:241 Internal Server Error: /test-paragraphs/b3d01adb-e481-403c-8374-2b0b6eb91d99/
Traceback (most recent call last):
  File "/Users/sumith/Documents/Projects/vercel/phenv/lib/python3.9/site-packages/django/db/backends/base/base.py", line 289, in ensure_connection
    self.connect()
  File "/Users/sumith/Documents/Projects/vercel/phenv/lib/python3.9/site-packages/django/utils/asyncio.py", line 26, in inner
    return func(*args, **kwargs)
  File "/Users/sumith/Documents/Projects/vercel/phenv/lib/python3.9/site-packages/django/db/backends/base/base.py", line 270, in connect
    self.connection = self.get_new_connection(conn_params)
  File "/Users/sumith/Documents/Projects/vercel/phenv/lib/python3.9/site-packages/django/utils/asyncio.py", line 26, in inner
    return func(*args, **kwargs)
  File "/Users/sumith/Documents/Projects/vercel/phenv/lib/python3.9/site-packages/django/db/backends/postgresql/base.py", line 275, in get_new_connection
    connection = self.Database.connect(**conn_params)
  File "/Users/sumith/Documents/Projects/vercel/phenv/lib/python3.9/site-packages/psycopg2/__init__.py", line 122, in connect
    conn = _connect(dsn, connection_factory=connection_factory, **kwasync)
psycopg2.OperationalError: connection to server at "173.249.1.23", port 5432 failed: Network is unreachable
	Is the server running on that host and accepting TCP/IP connections?


The above exception was the direct cause of the following exception:

Traceback (most recent call last):
  File "/Users/sumith/Documents/Projects/vercel/phenv/lib/python3.9/site-packages/django/core/handlers/exception.py", line 55, in inner
    response = get_response(request)
  File "/Users/sumith/Documents/Projects/vercel/phenv/lib/python3.9/site-packages/django/core/handlers/base.py", line 197, in _get_response
    response = wrapped_callback(request, *callback_args, **callback_kwargs)
  File "/Users/sumith/Documents/Projects/vercel/ph-django-main/recommendations/views.py", line 150, in get_test_paragraphs
    test_paragraph = TestParagraph.objects.get(test_record=test_id)
  File "/Users/sumith/Documents/Projects/vercel/phenv/lib/python3.9/site-packages/django/db/models/manager.py", line 87, in manager_method
    return getattr(self.get_queryset(), name)(*args, **kwargs)
  File "/Users/sumith/Documents/Projects/vercel/phenv/lib/python3.9/site-packages/django/db/models/query.py", line 633, in get
    num = len(clone)
  File "/Users/sumith/Documents/Projects/vercel/phenv/lib/python3.9/site-packages/django/db/models/query.py", line 380, in __len__
    self._fetch_all()
  File "/Users/sumith/Documents/Projects/vercel/phenv/lib/python3.9/site-packages/django/db/models/query.py", line 1881, in _fetch_all
    self._result_cache = list(self._iterable_class(self))
  File "/Users/sumith/Documents/Projects/vercel/phenv/lib/python3.9/site-packages/django/db/models/query.py", line 91, in __iter__
    results = compiler.execute_sql(
  File "/Users/sumith/Documents/Projects/vercel/phenv/lib/python3.9/site-packages/django/db/models/sql/compiler.py", line 1558, in execute_sql
    cursor = self.connection.cursor()
  File "/Users/sumith/Documents/Projects/vercel/phenv/lib/python3.9/site-packages/django/utils/asyncio.py", line 26, in inner
    return func(*args, **kwargs)
  File "/Users/sumith/Documents/Projects/vercel/phenv/lib/python3.9/site-packages/django/db/backends/base/base.py", line 330, in cursor
    return self._cursor()
  File "/Users/sumith/Documents/Projects/vercel/phenv/lib/python3.9/site-packages/django/db/backends/base/base.py", line 306, in _cursor
    self.ensure_connection()
  File "/Users/sumith/Documents/Projects/vercel/phenv/lib/python3.9/site-packages/django/utils/asyncio.py", line 26, in inner
    return func(*args, **kwargs)
  File "/Users/sumith/Documents/Projects/vercel/phenv/lib/python3.9/site-packages/django/db/backends/base/base.py", line 289, in ensure_connection
    self.connect()
  File "/Users/sumith/Documents/Projects/vercel/phenv/lib/python3.9/site-packages/django/db/utils.py", line 91, in __exit__
    raise dj_exc_value.with_traceback(traceback) from exc_value
  File "/Users/sumith/Documents/Projects/vercel/phenv/lib/python3.9/site-packages/django/db/backends/base/base.py", line 289, in ensure_connection
    self.connect()
  File "/Users/sumith/Documents/Projects/vercel/phenv/lib/python3.9/site-packages/django/utils/asyncio.py", line 26, in inner
    return func(*args, **kwargs)
  File "/Users/sumith/Documents/Projects/vercel/phenv/lib/python3.9/site-packages/django/db/backends/base/base.py", line 270, in connect
    self.connection = self.get_new_connection(conn_params)
  File "/Users/sumith/Documents/Projects/vercel/phenv/lib/python3.9/site-packages/django/utils/asyncio.py", line 26, in inner
    return func(*args, **kwargs)
  File "/Users/sumith/Documents/Projects/vercel/phenv/lib/python3.9/site-packages/django/db/backends/postgresql/base.py", line 275, in get_new_connection
    connection = self.Database.connect(**conn_params)
  File "/Users/sumith/Documents/Projects/vercel/phenv/lib/python3.9/site-packages/psycopg2/__init__.py", line 122, in connect
    conn = _connect(dsn, connection_factory=connection_factory, **kwasync)
django.db.utils.OperationalError: connection to server at "173.249.1.23", port 5432 failed: Network is unreachable
	Is the server running on that host and accepting TCP/IP connections?

2023-06-23 10:19:48 [ERROR] /Users/sumith/Documents/Projects/vercel/phenv/lib/python3.9/site-packages/django/utils/log.py:241 Internal Server Error: /api/recommend/
Traceback (most recent call last):
  File "/Users/sumith/Documents/Projects/vercel/phenv/lib/python3.9/site-packages/django/core/handlers/exception.py", line 55, in inner
    response = get_response(request)
  File "/Users/sumith/Documents/Projects/vercel/phenv/lib/python3.9/site-packages/django/core/handlers/base.py", line 197, in _get_response
    response = wrapped_callback(request, *callback_args, **callback_kwargs)
  File "/Users/sumith/Documents/Projects/vercel/phenv/lib/python3.9/site-packages/django/views/decorators/csrf.py", line 56, in wrapper_view
    return view_func(*args, **kwargs)
  File "/Users/sumith/Documents/Projects/vercel/ph-django-main/recommendations/views.py", line 443, in recommend_videos
    'selected_videos': selected_videoss
UnboundLocalError: local variable 'selected_videos' referenced before assignment
2023-06-23 13:52:27 [ERROR] /Users/sumith/Documents/Projects/vercel/phenv/lib/python3.9/site-packages/django/utils/log.py:241 Internal Server Error: /signup
Traceback (most recent call last):
  File "/Users/sumith/Documents/Projects/vercel/phenv/lib/python3.9/site-packages/django/core/handlers/exception.py", line 55, in inner
    response = get_response(request)
  File "/Users/sumith/Documents/Projects/vercel/phenv/lib/python3.9/site-packages/django/utils/deprecation.py", line 136, in __call__
    response = self.process_response(request, response)
  File "/Users/sumith/Documents/Projects/vercel/phenv/lib/python3.9/site-packages/django/middleware/common.py", line 108, in process_response
    return self.response_redirect_class(self.get_full_path_with_slash(request))
  File "/Users/sumith/Documents/Projects/vercel/phenv/lib/python3.9/site-packages/django/middleware/common.py", line 87, in get_full_path_with_slash
    raise RuntimeError(
RuntimeError: You called this URL via POST, but the URL doesn't end in a slash and you have APPEND_SLASH set. Django can't redirect to the slash URL while maintaining POST data. Change your form to point to localhost:8000/signup/ (note the trailing slash), or set APPEND_SLASH=False in your Django settings.
